Workbook

Sheet Regras
A1: Plano de numeração de blocos - PLC dos Bancos de Carga (CPU alvo: S7-1200F 1214FC; hoje 1515 provisória)
A2: Proposta v2 - 20/10/2026 - aprovada nos itens 1-5; nenhuma renumeração executada (tudo congelado até depois do teste de quinta/sexta).
A4: PARÂMETROS (células azuis = editáveis; todo o resto do arquivo recalcula)
A5: Base BT2 (DB) | B5: 50 | C5: confirmado (regra 19/10)
A6: Base BT1 (DB) | B6: 100 | C6: confirmado (regra 19/10)
A7: Base do 1º banco (DB) | B7: 150 | C7: proposto
A8: Tamanho da faixa de cada banco (DBs) | B8: 8 | C8: proposto
A9: Offset da instância de FB dentro do card BT (DB) | B9: 10 | C9: proposto (regra 19/10: 60-69 = instâncias)
A10: Base FB/FC lógica dos cards do BT | B10: 50 | C10: proposto
A11: Base FB/FC lógica do banco | B11: 100 | C11: proposto
A13: FÓRMULAS (a "lógica matemática")
A14: DB de dados do card (BT) | B14: Base_BT + offset_card | C14: ex.: DSE offset 2 -> BT2 = 52 / BT1 = 102
A15: FB do card (BT) | B15: Base_FB_BT + offset_card | C15: mesmo offset do DB do card; ex.: Etapas offset 6 -> FB56
A16: DB de instância do FB do card (BT) | B16: Base_BT + Offset_inst + offset_card | C16: ex.: Etapas -> BT2 = 66 / BT1 = 116
A17: Base do banco k (k=1..6) | B17: Base_1º_banco + Tamanho_faixa x (k-1) | C17: BC56 k=1 -> 150; BC400 k=2 -> 158; k=3..6 reserva
A18: DB de dados do banco | B18: Base_banco + offset (0 = chaves) | C18: BC56 = 150; BC400 = 158
A19: FB da lógica do banco (função f) | B19: Base_FB_banco + f | C19: f=0 setupChaves -> FB100
A20: DB de instância do FB do banco | B20: Base_banco + 4 + f | C20: BC56 setupChaves = 154; BC400 = 162
A22: PRINCÍPIOS
A23: 1. Dado (DB de card, acessado pelo Node-RED, S7_Optimized_Access FALSE) separado de lógica (FB/FC) e de instância (DB otimizado).
A24: 2. Lógica escrita uma vez, instanciada por escopo (BT1/BT2/banco). Nunca copiar FB.
A25: 3. Mesmo gabarito em todo escopo: BT1 = BT2 + 50 (mesmo offset); todos os bancos têm o mesmo gabarito interno.
A26: 4. DB do banco de carga não pertence ao BT (banco serve BT1 ou BT2); quem associa banco->BT é o Node-RED.
A27: 5. Nome simbólico com 3 dígitos (db052_...). Padrão: prefixo+número+_+descrição; FB: fb[nº]_[NomePascalCase]; ASCII.
A28: 6. Reserva em toda faixa. Faixa DB 200+ e FB/FC 200+ seguem livres para criação sob demanda.
A29: 7. Node-RED: UM endpoint S7 por PC (1214 tem 14 conexões S7, 8 reservadas); IP .156 (PC BT2) e .135 (PLC) em config, não em function nodes.
A31: LEGENDA DE CORES (abas seguintes)
A32: Confirmado / já existe
A33: Proposto
A34: Reserva

Sheet Blocos_novos
A1: Blocos novos - registro vivo (um bloco por linha; atualizar aqui sempre que criar ou aprovar um bloco)
A2: v3 - 22/10/2026. Os números e nomes saem das fórmulas das abas Regras e Bancos (não digite o número: mude o parâmetro lá). Células em azul = texto digitado por você/por mim; o resto recalcula.
A3: Como usar: (1) copie uma linha; (2) escolha CPU/Tipo/Escopo; (3) cole a fórmula do número (ex.: =Regras!$B$5+8) e do nome; (4) Situação: existe / aprovado - a criar / proposto / a definir / reserva; (5) a coluna Conflito acusa número repetido na mesma CPU e tipo.
A4: Regra 22/10: cada card tem o seu DB e o seu flow no Node-RED; o nome da aba do flow identifica o card (coluna "Flow Node-RED"). Cores da coluna Situação: verde = existe; amarelo = aprovado/proposto; cinza = a definir/reserva.
A6: Nº | B6: CPU | C6: Tipo | D6: Escopo | E6: Nº do bloco | F6: Nome simbólico | G6: Função | H6: Acesso | I6: Instância de / usa | J6: Escreve → Lê | K6: Card (tela) | L6: Flow Node-RED (aba) | M6: Situação | N6: Criado no TIA? | O6: Decisão / data | P6: Observação | Q6: Conflito?
A7: 1 | B7: PLC dos bancos | C7: DB | D7: BT2 | E7: =Regras!$B$5+2 -> 52 | F7: ="db"&TEXT(E7,"000")&"_BancoTeste2_Dse" -> db052_BancoTeste2_Dse | G7: Grandezas do DSE (leitura) | H7: Padrão (não otimizado) | I7: - | J7: DSE → Node-RED → HTML (via DB) | K7: Leitura das grandezas | L7: (flow do DSE - fora deste plano) | M7: existe | N7: Sim | O7: Confirmado 20/10 | P7: Hoje se chama db52_BancoTeste2_DSE; renomear só depois do teste a quente. | Q7: =IF(E7="","",IF(COUNTIFS($B$7:$B$60,B7,$C$7:$C$60,C7,$E$7:$E$60,E7)>1,"DUPLICADO","ok")) -> ok
A8: 2 | B8: PLC dos bancos | C8: DB | D8: BT2 | E8: =Regras!$B$5+3 -> 53 | F8: ="db"&TEXT(E8,"000")&"_BancoTeste2_SnapManual" -> db053_BancoTeste2_SnapManual | G8: Registro do ensaio manual (SNAP MANUAL) + preenchimento SAP | H8: Padrão (não otimizado) | I8: - | J8: HTML → Node-RED → PLC; PLC → Node-RED → HTML | K8: Registro do ensaio / Dados do ensaio | L8: Registro do Ensaio DB53 (API) | M8: existe | N8: Sim | O8: Confirmado 20/10 | P8: Rotas /api/ensaio/* (flow registro v1.4, 22/10). | Q8: =IF(E8="","",IF(COUNTIFS($B$7:$B$60,B8,$C$7:$C$60,C8,$E$7:$E$60,E8)>1,"DUPLICADO","ok")) -> ok
A9: 3 | B9: PLC dos bancos | C9: DB | D9: BT2 | E9: =Regras!$B$5+4 -> 54 | F9: ="db"&TEXT(E9,"000")&"_BancoTeste2_Parametros" -> db054_BancoTeste2_Parametros | G9: Parâmetros: faixas, faixa de água | H9: a definir | I9: - | J9: - | K9: Leitura das grandezas (Faixas) | L9: (a criar) | M9: proposto | N9: Não | O9: Citado pelo usuário | P9: Estrutura a definir. | Q9: =IF(E9="","",IF(COUNTIFS($B$7:$B$60,B9,$C$7:$C$60,C9,$E$7:$E$60,E9)>1,"DUPLICADO","ok")) -> ok
A10: 4 | B10: PLC dos bancos | C10: DB | D10: BC56 | E10: =Bancos!E2 -> 150 | F10: =Bancos!H2 -> db150_BC56_Chaves | G10: Chaves do BC56: cb.ligar / sb.ligada / setup | H10: Padrão (não otimizado) | I10: - | J10: HTML → Node-RED → PLC; PLC → Node-RED → HTML | K10: Cargas · banco de carga (BC56) | L10: Chaves BC56 (API) v2.2 | M10: existe | N10: Sim | O10: Confirmado 20/10 | P10: Layout: cb.ligar X0.0-1.7, sb.ligada X2.0-3.7. | Q10: =IF(E10="","",IF(COUNTIFS($B$7:$B$60,B10,$C$7:$C$60,C10,$E$7:$E$60,E10)>1,"DUPLICADO","ok")) -> ok
A11: 5 | B11: PLC dos bancos | C11: DB | D11: BC400 | E11: =Bancos!E3 -> 158 | F11: =Bancos!H3 -> db158_BC400_Chaves | G11: Chaves do BC400 | H11: Padrão (não otimizado) | I11: - | J11: HTML → Node-RED → PLC; PLC → Node-RED → HTML | K11: Cargas · banco de carga (BC400) | L11: Chaves BC400 (API) v2.2 | M11: existe | N11: Sim | O11: Confirmado 20/10 | P11: Mesmo gabarito do BC56. | Q11: =IF(E11="","",IF(COUNTIFS($B$7:$B$60,B11,$C$7:$C$60,C11,$E$7:$E$60,E11)>1,"DUPLICADO","ok")) -> ok
A12: 6 | B12: PLC dos bancos | C12: FB | D12: banco (f=0) | E12: =Regras!$B$11 -> 100 | F12: fb100_setupChaves | G12: Lógica do setup das chaves (fb100_setupChaves v0.2) | H12: Otimizado | I12: - | J12: - | K12: Cargas · Setup | L12: - | M12: existe | N12: Sim | O12: Confirmado 20/10 | P12: Substituiu o antigo FB200. | Q12: =IF(E12="","",IF(COUNTIFS($B$7:$B$60,B12,$C$7:$C$60,C12,$E$7:$E$60,E12)>1,"DUPLICADO","ok")) -> ok
A13: 7 | B13: PLC dos bancos | C13: DB | D13: BC56 (inst. f=0) | E13: =Bancos!G2 -> 154 | F13: =Bancos!I2 -> db154_BC56_SetupChaves | G13: Instância do FB100 para o BC56 | H13: Otimizado | I13: FB100 | J13: - | K13: - | L13: - | M13: existe | N13: Sim | O13: Confirmado 20/10 | Q13: =IF(E13="","",IF(COUNTIFS($B$7:$B$60,B13,$C$7:$C$60,C13,$E$7:$E$60,E13)>1,"DUPLICADO","ok")) -> ok
A14: 8 | B14: PLC dos bancos | C14: DB | D14: BC400 (inst. f=0) | E14: =Bancos!G3 -> 162 | F14: =Bancos!I3 -> db162_BC400_SetupChaves | G14: Instância do FB100 para o BC400 | H14: Otimizado | I14: FB100 | J14: - | K14: - | L14: - | M14: existe | N14: Sim | O14: Confirmado 20/10 | Q14: =IF(E14="","",IF(COUNTIFS($B$7:$B$60,B14,$C$7:$C$60,C14,$E$7:$E$60,E14)>1,"DUPLICADO","ok")) -> ok
A15: 9 | B15: PLC dos bancos | C15: FC | D15: BT2 | E15: 100 | F15: fc100_cardBancoCargas_BT2 | G15: Card banco de cargas - loopback sb.ligada (bancada) | H15: - | I15: - | J15: Escreve sb.ligada (some quando o FB101 entrar) | K15: Cargas · banco de carga | L15: - | M15: existe | N15: Sim | O15: Informado pelo usuário (aba Migracao) | P15: DESATIVAR o loopback ao ligar o FB101 (dois escritores no mesmo bit). | Q15: =IF(E15="","",IF(COUNTIFS($B$7:$B$60,B15,$C$7:$C$60,C15,$E$7:$E$60,E15)>1,"DUPLICADO","ok")) -> ok
A16: 10 | B16: PLC dos bancos | C16: FB | D16: banco (f=1) | E16: =Regras!$B$11+1 -> 101 | F16: ="fb"&TEXT(E16,"000")&"_ComEt200" -> fb101_ComEt200 | G16: Troca de sinais 1515 ⇄ ET200 por S7 PUT/GET (comando + vida; feedback + vida) | H16: Padrão (não otimizado) | I16: PUT / GET | J16: 1515 → ET200 (cmd); ET200 → 1515 (fb) | K16: Cargas · banco de carga | L16: - | M16: aprovado - a criar | N16: Não | O16: Aprovado 22/10 (usuário) | P16: Nome sugerido; o código SCL está em claude/PASSO_A_PASSO_PUT_GET_1515_ET200_v3.md (não compilado). | Q16: =IF(E16="","",IF(COUNTIFS($B$7:$B$60,B16,$C$7:$C$60,C16,$E$7:$E$60,E16)>1,"DUPLICADO","ok")) -> ok
A17: 11 | B17: PLC dos bancos | C17: DB | D17: BC56 (inst. f=1) | E17: =Bancos!G2+1 -> 155 | F17: ="db"&TEXT(E17,"000")&"_BC56_ComEt200" -> db155_BC56_ComEt200 | G17: Instância do FB101 para o BC56 (também é a área tx/rx) | H17: Padrão (não otimizado) | I17: FB101 | J17: - | K17: Cargas · banco de carga | L17: - | M17: aprovado - a criar | N17: Não | O17: Aprovado 22/10 (usuário) | P17: Fórmula: Base_banco + 4 + f. | Q17: =IF(E17="","",IF(COUNTIFS($B$7:$B$60,B17,$C$7:$C$60,C17,$E$7:$E$60,E17)>1,"DUPLICADO","ok")) -> ok
A18: 12 | B18: PLC dos bancos | C18: DB | D18: BC400 (inst. f=1) | E18: =Bancos!G3+1 -> 163 | F18: ="db"&TEXT(E18,"000")&"_BC400_ComEt200" -> db163_BC400_ComEt200 | G18: Instância do FB101 para o BC400 | H18: Padrão (não otimizado) | I18: FB101 | J18: - | K18: Cargas · banco de carga | L18: - | M18: aprovado - a criar | N18: Não | O18: Aprovado 22/10 (usuário) | P18: Só depois do BC56 validado. | Q18: =IF(E18="","",IF(COUNTIFS($B$7:$B$60,B18,$C$7:$C$60,C18,$E$7:$E$60,E18)>1,"DUPLICADO","ok")) -> ok
A19: 13 | B19: PLC dos bancos | C19: FB | D19: banco (f=2) | E19: =Regras!$B$11+2 -> 102 | F19: ="fb"&TEXT(E19,"000")&"_WatchdogComandos" -> fb102_WatchdogComandos | G19: Zera cb.ligar do banco se o pulso do Node-RED parar (watchdog de comandos) | H19: Otimizado | I19: - | J19: Node-RED → PLC (cb.hbNodeRed do DB58) | K19: Cargas · banco de carga | L19: - | M19: proposto | N19: Não | O19: Proposto 22/10 noite (aguarda D2/D3) | P19: Habilita=FALSE até existir o pulso do Node-RED no DB58. Ordem no OB: fb100 → fb102 → fb101. SCL em claude/PROTECAO_COMANDOS_PERSISTENTES_CB.md (não compilado). | Q19: =IF(E19="","",IF(COUNTIFS($B$7:$B$60,B19,$C$7:$C$60,C19,$E$7:$E$60,E19)>1,"DUPLICADO","ok")) -> ok
A20: 14 | B20: PLC dos bancos | C20: DB | D20: BC56 (inst. f=2) | E20: =Bancos!G2+2 -> 156 | F20: ="db"&TEXT(E20,"000")&"_BC56_WatchdogCmd" -> db156_BC56_WatchdogCmd | G20: Instância do FB102 para o BC56 | H20: Otimizado | I20: FB102 | J20: - | K20: Cargas · banco de carga | L20: - | M20: proposto | N20: Não | O20: Proposto 22/10 noite (aguarda D2) | P20: Fórmula: Base_banco + 4 + f. | Q20: =IF(E20="","",IF(COUNTIFS($B$7:$B$60,B20,$C$7:$C$60,C20,$E$7:$E$60,E20)>1,"DUPLICADO","ok")) -> ok
A21: 15 | B21: PLC dos bancos | C21: DB | D21: BC400 (inst. f=2) | E21: =Bancos!G3+2 -> 164 | F21: ="db"&TEXT(E21,"000")&"_BC400_WatchdogCmd" -> db164_BC400_WatchdogCmd | G21: Instância do FB102 para o BC400 | H21: Otimizado | I21: FB102 | J21: - | K21: Cargas · banco de carga | L21: - | M21: proposto | N21: Não | O21: Proposto 22/10 noite (aguarda D2) | P21: Só depois do BC56 validado. | Q21: =IF(E21="","",IF(COUNTIFS($B$7:$B$60,B21,$C$7:$C$60,C21,$E$7:$E$60,E21)>1,"DUPLICADO","ok")) -> ok
A22: 16 | B22: PLC dos bancos | C22: DB | D22: BT2 | E22: =Regras!$B$5+8 -> 58 | F22: ="db"&TEXT(E22,"000")&"_BancoTeste2_Modo" -> db058_BancoTeste2_Modo | G22: Batimento (heartbeat) PLC / Node-RED / HTML do card Modo - só sinaliza | H22: Padrão (não otimizado) | I22: - | J22: PLC → Node-RED (sb.hbPlc, nodeRedOk, htmlOk); Node-RED → PLC (cb.hbNodeRed, hbHtml) | K22: Modo | L22: Modo (API) - a criar depois do DB existir | M22: aprovado - a criar | N22: Não | O22: Aprovado 22/10 (usuário) | P22: Layout em claude/ESPECIFICACAO_DB58_MODO_HEARTBEAT.md v0.2. Perda de Node-RED/HTML só sinaliza (decisão 22/10; ação do PLC fica para o futuro). | Q22: =IF(E22="","",IF(COUNTIFS($B$7:$B$60,B22,$C$7:$C$60,C22,$E$7:$E$60,E22)>1,"DUPLICADO","ok")) -> ok
A23: 17 | B23: PLC dos bancos | C23: FB | D23: BT2 | E23: =Regras!$B$10+8 -> 58 | F23: ="fb"&TEXT(E23,"000")&"_Modo" -> fb058_Modo | G23: Lógica do heartbeat (opcional - o usuário faz a lógica) | H23: Otimizado | I23: - | J23: - | K23: Modo | L23: - | M23: proposto | N23: Não | O23: Esqueleto na especificação | P23: Opcional. | Q23: =IF(E23="","",IF(COUNTIFS($B$7:$B$60,B23,$C$7:$C$60,C23,$E$7:$E$60,E23)>1,"DUPLICADO","ok")) -> ok
A24: 18 | B24: PLC dos bancos | C24: DB | D24: BT2 (inst.) | E24: =Regras!$B$5+Regras!$B$9+8 -> 68 | F24: ="db"&TEXT(E24,"000")&"_BancoTeste2_ModoInst" -> db068_BancoTeste2_ModoInst | G24: Instância do FB58 | H24: Otimizado | I24: FB58 | J24: - | K24: Modo | L24: - | M24: proposto | N24: Não | O24: Esqueleto na especificação | P24: Só se o FB58 for usado. | Q24: =IF(E24="","",IF(COUNTIFS($B$7:$B$60,B24,$C$7:$C$60,C24,$E$7:$E$60,E24)>1,"DUPLICADO","ok")) -> ok
A25: 19 | B25: PLC dos bancos | C25: DB | D25: BC56 (status +1) | E25: =Bancos!F2 -> 151 | F25: ="db"&TEXT(E25,"000")&"_BC56_Status" -> db151_BC56_Status | G25: Status do banco (ex.: ComOk PLC⇄ET200) para o Node-RED | H25: a definir | I25: - | J25: PLC → Node-RED | K25: Cargas · banco de carga | L25: - | M25: a definir | N25: Não | O25: Pendente | P25: Quando existir, o flow chaves vai para v2.3 (sem mudar rotas). | Q25: =IF(E25="","",IF(COUNTIFS($B$7:$B$60,B25,$C$7:$C$60,C25,$E$7:$E$60,E25)>1,"DUPLICADO","ok")) -> ok
A26: 20 | B26: PLC dos bancos | C26: DB | D26: BC400 (status +1) | E26: =Bancos!F3 -> 159 | F26: ="db"&TEXT(E26,"000")&"_BC400_Status" -> db159_BC400_Status | G26: Status do banco BC400 | H26: a definir | I26: - | J26: PLC → Node-RED | K26: Cargas · banco de carga | L26: - | M26: a definir | N26: Não | O26: Pendente | Q26: =IF(E26="","",IF(COUNTIFS($B$7:$B$60,B26,$C$7:$C$60,C26,$E$7:$E$60,E26)>1,"DUPLICADO","ok")) -> ok
A27: 21 | B27: ET200 (Gerador_BC015) | C27: DB | D27: BC56 | E27: 10 | F27: ComBC56 | G27: Área de troca PUT/GET do BC56 no ET200 (cmd, vida1515, fb, vidaET) | H27: Padrão | I27: - | J27: 1515 (PUT/GET) ⇄ lógica do ET200 | K27: - | L27: - | M27: aprovado - a criar | N27: Não | O27: Número assumido (herdado da v1) | P27: DB do programa do ET200 (não é o DB10 "seletor comum" do plano do 1515). Confirmar se DB10 está livre no Gerador_BC015. | Q27: =IF(E27="","",IF(COUNTIFS($B$7:$B$60,B27,$C$7:$C$60,C27,$E$7:$E$60,E27)>1,"DUPLICADO","ok")) -> ok
A28: 22 | B28: ET200 (Gerador_BC015) | C28: DB | D28: BC400 | E28: 11 | F28: ComBC400 | G28: Área de troca PUT/GET do BC400 no ET200 | H28: Padrão | I28: - | J28: 1515 (PUT/GET) ⇄ lógica do ET200 | K28: - | L28: - | M28: proposto | N28: Não | O28: Número proposto | P28: Confirmar se DB11 está livre no Gerador_BC015. | Q28: =IF(E28="","",IF(COUNTIFS($B$7:$B$60,B28,$C$7:$C$60,C28,$E$7:$E$60,E28)>1,"DUPLICADO","ok")) -> ok
Q29: =IF(E29="","",IF(COUNTIFS($B$7:$B$60,B29,$C$7:$C$60,C29,$E$7:$E$60,E29)>1,"DUPLICADO","ok"))
Q30: =IF(E30="","",IF(COUNTIFS($B$7:$B$60,B30,$C$7:$C$60,C30,$E$7:$E$60,E30)>1,"DUPLICADO","ok"))
Q31: =IF(E31="","",IF(COUNTIFS($B$7:$B$60,B31,$C$7:$C$60,C31,$E$7:$E$60,E31)>1,"DUPLICADO","ok"))
Q32: =IF(E32="","",IF(COUNTIFS($B$7:$B$60,B32,$C$7:$C$60,C32,$E$7:$E$60,E32)>1,"DUPLICADO","ok"))
Q33: =IF(E33="","",IF(COUNTIFS($B$7:$B$60,B33,$C$7:$C$60,C33,$E$7:$E$60,E33)>1,"DUPLICADO","ok"))
Q34: =IF(E34="","",IF(COUNTIFS($B$7:$B$60,B34,$C$7:$C$60,C34,$E$7:$E$60,E34)>1,"DUPLICADO","ok"))
Q35: =IF(E35="","",IF(COUNTIFS($B$7:$B$60,B35,$C$7:$C$60,C35,$E$7:$E$60,E35)>1,"DUPLICADO","ok"))
Q36: =IF(E36="","",IF(COUNTIFS($B$7:$B$60,B36,$C$7:$C$60,C36,$E$7:$E$60,E36)>1,"DUPLICADO","ok"))
A38: Resumo por situação
B39: existe | C39: =COUNTIF($M$7:$M$36,B39) -> 8
B40: aprovado - a criar | C40: =COUNTIF($M$7:$M$36,B40) -> 5
B41: proposto | C41: =COUNTIF($M$7:$M$36,B41) -> 7
B42: a definir | C42: =COUNTIF($M$7:$M$36,B42) -> 2
...

Sheet Faixas
A1: Tipo | B1: De | C1: Até | D1: Escopo | E1: Observação
A2: DB | B2: 1 | C2: 49 | D2: COMUM (todos) | E2: seletor manual/auto, config, diagnóstico
A3: DB | B3: =Regras!$B$5 -> 50 | C3: =Regras!$B$6-1 -> 99 | D3: BT2 | E3: +0..+9 dados dos cards; +10..+19 instâncias; +20..+49 reserva
A4: DB | B4: =Regras!$B$6 -> 100 | C4: =Regras!$B$7-1 -> 149 | D4: BT1 | E4: mesmo gabarito do BT2
A5: DB | B5: =Regras!$B$7 -> 150 | C5: =Regras!$B$7+6*Regras!$B$8-1 -> 197 | D5: BANCOS DE CARGA (6 posições) | E5: BC56, BC400 + 4 reservas
A6: DB | B6: =Regras!$B$7+6*Regras!$B$8 -> 198 | C6: 199 | D6: reserva
A7: DB | B7: 200 | C7: 65535 | D7: livre (criação sob demanda) | E7: nada definitivo; limite do datasheet 1214FC = 65535
A8: FB/FC | B8: 1 | C8: 49 | D8: comum | E8: utilidades, mapeamento de I/O, diagnóstico
A9: FB/FC | B9: =Regras!$B$10 -> 50 | C9: =Regras!$B$11-1 -> 99 | D9: lógica dos cards do BT | E9: 1 FB, 2 instâncias (BT1/BT2)
A10: FB/FC | B10: =Regras!$B$11 -> 100 | C10: 149 | D10: lógica do banco de carga | E10: 1 FB, 1 instância por banco
A11: FB/FC | B11: 150 | C11: 199 | D11: reserva
A12: FB/FC | B12: 200 | C12: 65535 | D12: livre
A13: OB | B13: 1 | C13: 1 | D13: Main | E13: só chama FCs de área
A14: OB | B14: 100 | C14: 100 | D14: Startup
A15: OB | B15: 30 | C15: 38 | D15: cíclicos | E15: reserva - só se necessário (OB limitado só pela RAM)

Sheet BT_gabarito
A1: Offset | B1: Conteúdo (card / popup) | C1: Status | D1: DB BT2 | E1: Nome BT2 | F1: FB do card BT2 | G1: DB instância BT2 | I1: DB BT1 | J1: Nome BT1 | K1: FB do card BT1 | L1: DB instância BT1 | M1: Tipo
A2: 0 | B2: reserva | D2: =Regras!$B$5+A2 -> 50 | I2: =Regras!$B$6+A2 -> 100 | M2: res
A3: 1 | B3: reserva | D3: =Regras!$B$5+A3 -> 51 | I3: =Regras!$B$6+A3 -> 101 | M3: res
A4: 2 | B4: DSE (SB_DSE) - Grandezas, Motor | C4: existe: DB52 db52_BancoTeste2_DSE (DB52 real) | D4: =Regras!$B$5+A4 -> 52 | E4: ="db"&TEXT(D4,"000")&"_BancoTeste2_Dse" -> db052_BancoTeste2_Dse | F4: =Regras!$B$10+A4 -> 52 | G4: =Regras!$B$5+Regras!$B$9+A4 -> 62 | I4: =Regras!$B$6+A4 -> 102 | J4: ="db"&TEXT(I4,"000")&"_BancoTeste1_Dse" -> db102_BancoTeste1_Dse | L4: =Regras!$B$6+Regras!$B$9+A4 -> 112 | M4: conf
A5: 3 | B5: Registro / SNAP MANUAL - Registro do ensaio, Resultado | C5: existe: DB53 SNAP MANUAL | D5: =Regras!$B$5+A5 -> 53 | E5: ="db"&TEXT(D5,"000")&"_BancoTeste2_SnapManual" -> db053_BancoTeste2_SnapManual | F5: =Regras!$B$10+A5 -> 53 | G5: =Regras!$B$5+Regras!$B$9+A5 -> 63 | I5: =Regras!$B$6+A5 -> 103 | J5: ="db"&TEXT(I5,"000")&"_BancoTeste1_SnapManual" -> db103_BancoTeste1_SnapManual | L5: =Regras!$B$6+Regras!$B$9+A5 -> 113 | M5: conf
A6: 4 | B6: Parâmetros - Faixas, faixa de água | C6: DB54 (citado pelo usuário); estrutura a definir | D6: =Regras!$B$5+A6 -> 54 | E6: ="db"&TEXT(D6,"000")&"_BancoTeste2_Parametros" -> db054_BancoTeste2_Parametros | F6: =Regras!$B$10+A6 -> 54 | G6: =Regras!$B$5+Regras!$B$9+A6 -> 64 | I6: =Regras!$B$6+A6 -> 104 | J6: ="db"&TEXT(I6,"000")&"_BancoTeste1_Parametros" -> db104_BancoTeste1_Parametros | L6: =Regras!$B$6+Regras!$B$9+A6 -> 114 | M6: prop
A7: 5 | B7: reserva (antigo DB55 Chaves foi para o banco) | D7: =Regras!$B$5+A7 -> 55 | I7: =Regras!$B$6+A7 -> 105 | M7: res
A8: 6 | B8: Etapas do ensaio (estado, cronômetro, comandos) | C8: a desenvolver | D8: =Regras!$B$5+A8 -> 56 | E8: ="db"&TEXT(D8,"000")&"_BancoTeste2_Etapas" -> db056_BancoTeste2_Etapas | F8: =Regras!$B$10+A8 -> 56 | G8: =Regras!$B$5+Regras!$B$9+A8 -> 66 | I8: =Regras!$B$6+A8 -> 106 | J8: ="db"&TEXT(I8,"000")&"_BancoTeste1_Etapas" -> db106_BancoTeste1_Etapas | L8: =Regras!$B$6+Regras!$B$9+A8 -> 116 | M8: prop
A9: 7 | B9: Dados do ensaio (SAP; "ensaio em andamento") | C9: a desenvolver (hoje preenchimento está no DB53) | D9: =Regras!$B$5+A9 -> 57 | E9: ="db"&TEXT(D9,"000")&"_BancoTeste2_DadosEnsaio" -> db057_BancoTeste2_DadosEnsaio | F9: =Regras!$B$10+A9 -> 57 | G9: =Regras!$B$5+Regras!$B$9+A9 -> 67 | I9: =Regras!$B$6+A9 -> 107 | J9: ="db"&TEXT(I9,"000")&"_BancoTeste1_DadosEnsaio" -> db107_BancoTeste1_DadosEnsaio | L9: =Regras!$B$6+Regras!$B$9+A9 -> 117 | M9: prop
A10: 8 | B10: Modo (tipo, salvamento, gráfico, Node-RED manual/auto) | C10: a desenvolver | D10: =Regras!$B$5+A10 -> 58 | E10: ="db"&TEXT(D10,"000")&"_BancoTeste2_Modo" -> db058_BancoTeste2_Modo | F10: =Regras!$B$10+A10 -> 58 | G10: =Regras!$B$5+Regras!$B$9+A10 -> 68 | I10: =Regras!$B$6+A10 -> 108 | J10: ="db"&TEXT(I10,"000")&"_BancoTeste1_Modo" -> db108_BancoTeste1_Modo | L10: =Regras!$B$6+Regras!$B$9+A10 -> 118 | M10: prop
A11: 9 | B11: reserva | D11: =Regras!$B$5+A11 -> 59 | I11: =Regras!$B$6+A11 -> 109 | M11: res
A13: +10..+19: instâncias de FB (otimizado) | +20..+49: reserva do BT. FB do card só existe se o card tiver lógica (reservado mesmo se não usado).

Sheet Bancos
A1: Banco | B1: Potência | C1: k (posição) | D1: Base | E1: DB Chaves (+0 cb/sb/setup) | F1: DB status banco (+1) a definir | G1: DB instância FB100 setupChaves (+4) | H1: Nome DB Chaves | I1: Nome instância | J1: Hoje
A2: BC56 | B2: 56 kW | C2: 1 | D2: =Regras!$B$7+Regras!$B$8*(C2-1) -> 150 | E2: =D2 -> 150 | F2: =D2+1 -> 151 | G2: =D2+4 -> 154 | H2: ="db"&TEXT(E2,"000")&"_BC56_Chaves" -> db150_BC56_Chaves | I2: ="db"&TEXT(G2,"000")&"_BC56_SetupChaves" -> db154_BC56_SetupChaves | J2: DB55 (56+400 juntos) / DB200 (56 kW) ou DB201 (400 kW)
A3: BC400 | B3: 400 kW | C3: 2 | D3: =Regras!$B$7+Regras!$B$8*(C3-1) -> 158 | E3: =D3 -> 158 | F3: =D3+1 -> 159 | G3: =D3+4 -> 162 | H3: ="db"&TEXT(E3,"000")&"_BC400_Chaves" -> db158_BC400_Chaves | I3: ="db"&TEXT(G3,"000")&"_BC400_SetupChaves" -> db162_BC400_SetupChaves | J3: DB55 / DB201
A4: reserva A | C4: 3 | D4: =Regras!$B$7+Regras!$B$8*(C4-1) -> 166 | E4: =D4 -> 166 | F4: =D4+1 -> 167 | G4: =D4+4 -> 170
A5: reserva B | C5: 4 | D5: =Regras!$B$7+Regras!$B$8*(C5-1) -> 174 | E5: =D5 -> 174 | F5: =D5+1 -> 175 | G5: =D5+4 -> 178
A6: reserva C | C6: 5 | D6: =Regras!$B$7+Regras!$B$8*(C6-1) -> 182 | E6: =D6 -> 182 | F6: =D6+1 -> 183 | G6: =D6+4 -> 186
A7: reserva D | C7: 6 | D7: =Regras!$B$7+Regras!$B$8*(C7-1) -> 190 | E7: =D7 -> 190 | F7: =D7+1 -> 191 | G7: =D7+4 -> 194
A9: Gabarito interno: +0 Chaves (card Cargas + popup Chaves) | +1 status/medição do banco | +2,+3 reserva | +4..+7 instâncias (f=0 setupChaves; f=1..3 futuras).
A10: Hoje o DB55 guarda os 2 bancos (sufixos 56/400). No gabarito novo cada banco tem seu DB de chaves, arrays sem sufixo (muda a estrutura do DB55 - só após a janela de teste).
A11: Nomes usam BC56/BC400 (decisão do usuário 20/10); posições k=3..6 reservadas, sem nome até existirem.

Sheet Cards_popups
A1: Card (tela) | B1: Sub-módulos | C1: Popups (medidor_gerador_v1.9.38.html) | D1: PLC (proposto)
A2: Modo (novo v1.9.38) | B2: fonte REAL/DEMO, tipo, salvamento, Node-RED, gráfico | C2: dlgModo | D2: BT +8 (fonte REAL/DEMO é só da tela)
A3: Etapas do ensaio | B3: cronômetro; INICIAR/PAUSAR/ZERAR/FINALIZAR; barras de etapa; lâmpada | C3: dlgDados (Dados do ensaio), dlgEtapa, dlgFim, dlgResalva | D3: BT +6 e +7
A4: Gráfico | B4: carga x tempo; exportar PNG/CSV/PDF | C4: - | D4: nenhum (só tela)
A5: Leitura das grandezas | B5: carga, tensão, corrente, geral (kW, água, rpm, bateria); Gerar PDF (v1.9.38) | C5: dlgGrand, dlgMotor, dlgParam (Faixas), dlgAgua | D5: BT +2 (DSE) e +4 (parâmetros)
A6: Simulação (só Demo) | B6: operador, slider, velocidade | C6: - | D6: nenhum
A7: Cargas · banco | B7: chaves; aplicado/DSE/diferença | C7: dlgChaves | D7: banco +0 (e +1)
A8: Registro do ensaio | B8: tabela por etapa; strip do ensaio | C8: dlgRes (Resultado), dlgVer | D8: BT +3
A9: Barra superior | B9: Dados, Amostras, Servidor, Demo, versão | C9: dlgDados, dlgReg (Amostras), dlgSrv, dlgDemo, dlgVer | D9: nenhum (tela / Node-RED)
A11: Quais popups gravam no PLC além de DB52/53/55 não está confirmado nos arquivos: coluna PLC é proposta.

Sheet Migracao
A1: Hoje | B1: Novo nº (1º destino) | C1: Novo nome | D1: Observação
A2: DB52 db52_BancoTeste2_DSE | B2: =Regras!B5+2 -> 52 | C2: db052_BancoTeste2_DSE | D2: mantém o número; só renomeia. Não renomiei por DSE e nome do fabricante
A3: DB53 SNAP MANUAL | B3: =Regras!B5+3 -> 53 | C3: db053_BancoTeste2_SnapManual | D3: mantém o número. Feito
A4: DB54 parâmetros | B4: =Regras!B5+4 -> 54 | C4: db054_BancoTeste2_Parametros | D4: mantém. Feito
A5: DB55 chaves (56+400) | B5: =Bancos!E2 -> 150 | C5: db150_BC56_Chaves e db158_BC400_Chaves | D5: ESTRUTURA MUDA: um DB por banco, arrays sem sufixo. Já criei esta em teste no PLC . Feito
A6: FB200 fb200_setupChaves | B6: =Regras!B11 -> 100 | C6: fb100_setupChaves | D6: mesmo código, novo número. Feito
A7: DB200 (instância 56 kW) | B7: =Bancos!G2 -> 154 | C7: db154_BC56_SetupChaves | D7: Já criei esta em teste no PLC
A8: DB201 (instância 400 kW) | B8: =Bancos!G3 -> 162 | C8: db162_BC400_SetupChaves | D8: Já criei esta em teste no PLC
A9: FC100 Card banco de Cargas | C9: fc100_cardBancoCargas_BT2 | D9: Já criei esta em teste no PLC
A15: Ordem: 1 congelar; 2 teste quinta/sexta (corrige só o que falhar); 3 criar DBs novos em paralelo; 4 trocar endereços S7 nos JSONs (tabela acima); 5 validar; 6 remover antigos.
A16: Ao trocar 1515 -> 1214: reconfirmar PUT/GET, conexões S7 (14, 8 reservadas), tamanho total dos DBs vs 200 kB de memória de trabalho.

Sheet CPU_1214FC
A1: Item | B1: Valor
A2: Memória de trabalho | B2: 200 kB
A3: Memória de carga | B3: 4 MB
A4: Área retentiva | B4: 14 kB
A5: Blocos endereçáveis (DB+FC+FB+cont.+temp.) | B5: 1 a 65535
A6: OB | B6: limitado só pela RAM de código
A7: Conexões S7 | B7: 8 reservadas / 14 máx.
A9: Fonte: S7-1200F CPU 1214FC DC/DC/DC, 6ES7214-1AF40-0XB0, datasheet 11/22/2023 (A700000006981255.pdf).

Sheet Pendencias
A1: Item | B1: Status
A2: Estrutura detalhada dos DBs novos (BT+4, +6, +7, +8; banco +1) | B2: a desenvolver
A3: DB seletor manual/auto = DB10 (comum) | B3: a desenvolver
A4: Node-RED: um flow por card, um endpoint S7 por PC | B4: aguardando JSONs (usuário ensina depois)
A5: R teórico, reset da base no STOP do gerador, Habilitada como CB/SB (FB setupChaves) | B5: assumidos - confirmar
A6: Quais popups gravam no PLC | B6: confirmar
A7: Heartbeat: criar DB58 no PLC (aprovado 22/10); depois o flow "Modo (API)" e as bolinhas reais | B7: a desenvolver (aguarda o DB58)
A8: PUT/GET 1515 ⇄ ET200: criar FB101, DB155 e DB163 (aprovados 22/10) + DB10/DB11 no ET200 | B8: a desenvolver (usuário no TIA; SCL v3 na pasta claude/)
A9: Proteção cbLigar: aprovar FB102/DB156/DB164 (D2), criar flow "Modo (API)" com pulso do Node-RED no DB58 (D3), limite do vigia 30 s (D1), layout do DB52 para validade (D4) | B9: aguardando decisões (claude/PROTECAO_COMANDOS_PERSISTENTES_CB.md)
A10: Status do banco (DB151/DB159): definir conteúdo (ex.: ComOk) | B10: a definir
A11: Código das ocorrências (COM/DSE/CHV/ENS/SIS/PLC): confirmar o padrão AAA-NNN | B11: aguardando confirmação (claude/PADRAO_OCORRENCIAS_MENSAGENS_FALHAS.md)
